[2025-09-15T09:22:21.453+0000] {taskinstance.py:1956} INFO - Dependencies all met for dep_context=non-requeueable deps ti=<TaskInstance: ml_pipeline_orchestration.log_experiments scheduled__2025-09-14T00:00:00+00:00 [queued]>
[2025-09-15T09:22:21.477+0000] {taskinstance.py:1956} INFO - Dependencies all met for dep_context=requeueable deps ti=<TaskInstance: ml_pipeline_orchestration.log_experiments scheduled__2025-09-14T00:00:00+00:00 [queued]>
[2025-09-15T09:22:21.479+0000] {taskinstance.py:2170} INFO - Starting attempt 1 of 2
[2025-09-15T09:22:21.523+0000] {taskinstance.py:2191} INFO - Executing <Task(DockerOperator): log_experiments> on 2025-09-14 00:00:00+00:00
[2025-09-15T09:22:21.532+0000] {standard_task_runner.py:60} INFO - Started process 430 to run task
[2025-09-15T09:22:21.541+0000] {standard_task_runner.py:87} INFO - Running: ['***', 'tasks', 'run', 'ml_pipeline_orchestration', 'log_experiments', 'scheduled__2025-09-14T00:00:00+00:00', '--job-id', '13', '--raw', '--subdir', 'DAGS_FOLDER/orchestration.py', '--cfg-path', '/tmp/tmprnqsgmwx']
[2025-09-15T09:22:21.546+0000] {standard_task_runner.py:88} INFO - Job 13: Subtask log_experiments
[2025-09-15T09:22:21.745+0000] {task_command.py:423} INFO - Running <TaskInstance: ml_pipeline_orchestration.log_experiments scheduled__2025-09-14T00:00:00+00:00 [running]> on host 6003dd60b185
[2025-09-15T09:22:22.067+0000] {taskinstance.py:2480} INFO - Exporting env vars: AIRFLOW_CTX_DAG_OWNER='Jerr-williams' AIRFLOW_CTX_DAG_ID='ml_pipeline_orchestration' AIRFLOW_CTX_TASK_ID='log_experiments' AIRFLOW_CTX_EXECUTION_DATE='2025-09-14T00:00:00+00:00' AIRFLOW_CTX_TRY_NUMBER='1' AIRFLOW_CTX_DAG_RUN_ID='scheduled__2025-09-14T00:00:00+00:00'
[2025-09-15T09:22:22.232+0000] {docker.py:359} INFO - Starting docker container from image 972111245465383674563253/prediction-apps:latest
[2025-09-15T09:22:34.434+0000] {docker.py:429} INFO - /usr/local/lib/python3.12/site-packages/mlflow/utils/requirements_utils.py:20: UserWarning: pkg_resources is deprecated as an API. See https://setuptools.pypa.io/en/latest/pkg_resources.html. The pkg_resources package is slated for removal as early as 2025-11-30. Refrain from using this package or pin to Setuptools<81.
  import pkg_resources  # noqa: TID251
[2025-09-15T09:23:45.273+0000] {docker.py:429} INFO - 2025/09/15 09:23:45 WARNING mlflow.utils.git_utils: Failed to import Git (the Git executable is probably not on your PATH), so Git SHA is not available. Error: Failed to initialize: Bad git executable.
The git executable must be specified in one of the following ways:
    - be included in your $PATH
    - be set via $GIT_PYTHON_GIT_EXECUTABLE
    - explicitly set via git.refresh(<full-path-to-git-executable>)

All git commands will error until this is rectified.

This initial message can be silenced or aggravated in the future by setting the
$GIT_PYTHON_REFRESH environment variable. Use one of the following values:
    - quiet|q|silence|s|silent|none|n|0: for no message or exception
    - warn|w|warning|log|l|1: for a warning message (logging level CRITICAL, displayed by default)
    - error|e|exception|raise|r|2: for a raised exception

Example:
    export GIT_PYTHON_REFRESH=quiet
[2025-09-15T09:26:51.669+0000] {docker.py:429} INFO - Logging the Experiements
Error setting up MLflow: API request to https://dagshub.com/jerremiahwilly/Customer-churn.mlflow/api/2.0/mlflow/experiments/get-by-name failed with exception HTTPSConnectionPool(host='dagshub.com', port=443): Max retries exceeded with url: /jerremiahwilly/Customer-churn.mlflow/api/2.0/mlflow/experiments/get-by-name?experiment_name=Customer+Churn+Prediction (Caused by NameResolutionError("<urllib3.connection.HTTPSConnection object at 0x7fec273ab530>: Failed to resolve 'dagshub.com' ([Errno -2] Name or service not known)"))
Error tracking logistic_regression: API request to https://dagshub.com/jerremiahwilly/Customer-churn.mlflow/api/2.0/mlflow/runs/create failed with exception HTTPSConnectionPool(host='dagshub.com', port=443): Max retries exceeded with url: /jerremiahwilly/Customer-churn.mlflow/api/2.0/mlflow/runs/create (Caused by NameResolutionError("<urllib3.connection.HTTPSConnection object at 0x7fec27090b60>: Failed to resolve 'dagshub.com' ([Errno -2] Name or service not known)"))
Error tracking random_forest: API request to https://dagshub.com/jerremiahwilly/Customer-churn.mlflow/api/2.0/mlflow/runs/create failed with exception HTTPSConnectionPool(host='dagshub.com', port=443): Max retries exceeded with url: /jerremiahwilly/Customer-churn.mlflow/api/2.0/mlflow/runs/create (Caused by NameResolutionError("<urllib3.connection.HTTPSConnection object at 0x7fec273a9580>: Failed to resolve 'dagshub.com' ([Errno -2] Name or service not known)"))
Error tracking Gradient_Boosting: API request to https://dagshub.com/jerremiahwilly/Customer-churn.mlflow/api/2.0/mlflow/runs/create failed with exception HTTPSConnectionPool(host='dagshub.com', port=443): Max retries exceeded with url: /jerremiahwilly/Customer-churn.mlflow/api/2.0/mlflow/runs/create (Caused by NameResolutionError("<urllib3.connection.HTTPSConnection object at 0x7fec27090560>: Failed to resolve 'dagshub.com' ([Errno -2] Name or service not known)"))
Successfully logged 0 experiments
[2025-09-15T09:26:54.129+0000] {taskinstance.py:1138} INFO - Marking task as SUCCESS. dag_id=ml_pipeline_orchestration, task_id=log_experiments, execution_date=20250914T000000, start_date=20250915T092221, end_date=20250915T092654
[2025-09-15T09:26:54.204+0000] {local_task_job_runner.py:234} INFO - Task exited with return code 0
[2025-09-15T09:26:54.328+0000] {taskinstance.py:3280} INFO - 1 downstream tasks scheduled from follow-on schedule check
