[2025-09-09T02:22:19.355+0000] {taskinstance.py:1956} INFO - Dependencies all met for dep_context=non-requeueable deps ti=<TaskInstance: ml_pipeline_orchestration.train_model scheduled__2025-09-08T00:00:00+00:00 [queued]>
[2025-09-09T02:22:19.402+0000] {taskinstance.py:1956} INFO - Dependencies all met for dep_context=requeueable deps ti=<TaskInstance: ml_pipeline_orchestration.train_model scheduled__2025-09-08T00:00:00+00:00 [queued]>
[2025-09-09T02:22:19.405+0000] {taskinstance.py:2170} INFO - Starting attempt 1 of 2
[2025-09-09T02:22:19.649+0000] {taskinstance.py:2191} INFO - Executing <Task(DockerOperator): train_model> on 2025-09-08 00:00:00+00:00
[2025-09-09T02:22:19.659+0000] {standard_task_runner.py:60} INFO - Started process 521 to run task
[2025-09-09T02:22:19.674+0000] {standard_task_runner.py:87} INFO - Running: ['***', 'tasks', 'run', 'ml_pipeline_orchestration', 'train_model', 'scheduled__2025-09-08T00:00:00+00:00', '--job-id', '5', '--raw', '--subdir', 'DAGS_FOLDER/orchestration.py', '--cfg-path', '/tmp/tmpf2d2t0rv']
[2025-09-09T02:22:19.684+0000] {standard_task_runner.py:88} INFO - Job 5: Subtask train_model
[2025-09-09T02:22:19.986+0000] {task_command.py:423} INFO - Running <TaskInstance: ml_pipeline_orchestration.train_model scheduled__2025-09-08T00:00:00+00:00 [running]> on host 8fa5420c069d
[2025-09-09T02:22:20.358+0000] {taskinstance.py:2480} INFO - Exporting env vars: AIRFLOW_CTX_DAG_OWNER='Jerr-williams' AIRFLOW_CTX_DAG_ID='ml_pipeline_orchestration' AIRFLOW_CTX_TASK_ID='train_model' AIRFLOW_CTX_EXECUTION_DATE='2025-09-08T00:00:00+00:00' AIRFLOW_CTX_TRY_NUMBER='1' AIRFLOW_CTX_DAG_RUN_ID='scheduled__2025-09-08T00:00:00+00:00'
[2025-09-09T02:22:20.810+0000] {docker.py:486} INFO - Pulling docker image 972111245465383674563253/prediction-app:latest")
[2025-09-09T02:22:20.872+0000] {taskinstance.py:2698} ERROR - Task failed with exception
Traceback (most recent call last):
  File "/home/airflow/.local/lib/python3.8/site-packages/docker/api/client.py", line 265, in _raise_for_status
    response.raise_for_status()
  File "/home/airflow/.local/lib/python3.8/site-packages/requests/models.py", line 1021, in raise_for_status
    raise HTTPError(http_error_msg, response=self)
requests.exceptions.HTTPError: 400 Client Error: Bad Request for url: http+docker://localhost/v1.51/images/create?tag=latest%22%29&fromImage=972111245465383674563253%2Fprediction-app

The above exception was the direct cause of the following exception:

Traceback (most recent call last):
  File "/home/airflow/.local/lib/python3.8/site-packages/airflow/models/taskinstance.py", line 433, in _execute_task
    result = execute_callable(context=context, **execute_callable_kwargs)
  File "/home/airflow/.local/lib/python3.8/site-packages/airflow/providers/docker/operators/docker.py", line 488, in execute
    for output in self.cli.pull(self.image, stream=True, decode=True):
  File "/home/airflow/.local/lib/python3.8/site-packages/docker/api/image.py", line 429, in pull
    self._raise_for_status(response)
  File "/home/airflow/.local/lib/python3.8/site-packages/docker/api/client.py", line 267, in _raise_for_status
    raise create_api_error_from_http_exception(e) from e
  File "/home/airflow/.local/lib/python3.8/site-packages/docker/errors.py", line 39, in create_api_error_from_http_exception
    raise cls(e, response=response, explanation=explanation) from e
docker.errors.APIError: 400 Client Error for http+docker://localhost/v1.51/images/create?tag=latest%22%29&fromImage=972111245465383674563253%2Fprediction-app: Bad Request ("invalid tag format")
[2025-09-09T02:22:20.930+0000] {taskinstance.py:1138} INFO - Marking task as UP_FOR_RETRY. dag_id=ml_pipeline_orchestration, task_id=train_model, execution_date=20250908T000000, start_date=20250909T022219, end_date=20250909T022220
[2025-09-09T02:22:20.993+0000] {standard_task_runner.py:107} ERROR - Failed to execute job 5 for task train_model (400 Client Error for http+docker://localhost/v1.51/images/create?tag=latest%22%29&fromImage=972111245465383674563253%2Fprediction-app: Bad Request ("invalid tag format"); 521)
[2025-09-09T02:22:21.043+0000] {local_task_job_runner.py:234} INFO - Task exited with return code 1
[2025-09-09T02:22:21.125+0000] {taskinstance.py:3280} INFO - 0 downstream tasks scheduled from follow-on schedule check
