[2025-09-13T16:31:20.451+0000] {taskinstance.py:1956} INFO - Dependencies all met for dep_context=non-requeueable deps ti=<TaskInstance: ml_pipeline_orchestration.train_model manual__2025-09-13T16:26:00.877071+00:00 [queued]>
[2025-09-13T16:31:20.476+0000] {taskinstance.py:1956} INFO - Dependencies all met for dep_context=requeueable deps ti=<TaskInstance: ml_pipeline_orchestration.train_model manual__2025-09-13T16:26:00.877071+00:00 [queued]>
[2025-09-13T16:31:20.477+0000] {taskinstance.py:2170} INFO - Starting attempt 2 of 2
[2025-09-13T16:31:20.575+0000] {taskinstance.py:2191} INFO - Executing <Task(DockerOperator): train_model> on 2025-09-13 16:26:00.877071+00:00
[2025-09-13T16:31:20.587+0000] {standard_task_runner.py:60} INFO - Started process 613 to run task
[2025-09-13T16:31:20.597+0000] {standard_task_runner.py:87} INFO - Running: ['***', 'tasks', 'run', 'ml_pipeline_orchestration', 'train_model', 'manual__2025-09-13T16:26:00.877071+00:00', '--job-id', '99', '--raw', '--subdir', 'DAGS_FOLDER/another.py', '--cfg-path', '/tmp/tmp129lw6n5']
[2025-09-13T16:31:20.604+0000] {standard_task_runner.py:88} INFO - Job 99: Subtask train_model
[2025-09-13T16:31:20.800+0000] {task_command.py:423} INFO - Running <TaskInstance: ml_pipeline_orchestration.train_model manual__2025-09-13T16:26:00.877071+00:00 [running]> on host debc6c619bab
[2025-09-13T16:31:21.264+0000] {taskinstance.py:2480} INFO - Exporting env vars: AIRFLOW_CTX_DAG_OWNER='Jeremiah-williams' AIRFLOW_CTX_DAG_ID='ml_pipeline_orchestration' AIRFLOW_CTX_TASK_ID='train_model' AIRFLOW_CTX_EXECUTION_DATE='2025-09-13T16:26:00.877071+00:00' AIRFLOW_CTX_TRY_NUMBER='2' AIRFLOW_CTX_DAG_RUN_ID='manual__2025-09-13T16:26:00.877071+00:00'
[2025-09-13T16:31:21.430+0000] {docker.py:359} INFO - Starting docker container from image 972111245465383674563253/prediction-apps:latest
[2025-09-13T16:31:21.529+0000] {taskinstance.py:2698} ERROR - Task failed with exception
Traceback (most recent call last):
  File "/home/airflow/.local/lib/python3.8/site-packages/docker/api/client.py", line 265, in _raise_for_status
    response.raise_for_status()
  File "/home/airflow/.local/lib/python3.8/site-packages/requests/models.py", line 1021, in raise_for_status
    raise HTTPError(http_error_msg, response=self)
requests.exceptions.HTTPError: 400 Client Error: Bad Request for url: http+docker://localhost/v1.51/containers/create

The above exception was the direct cause of the following exception:

Traceback (most recent call last):
  File "/home/airflow/.local/lib/python3.8/site-packages/airflow/models/taskinstance.py", line 433, in _execute_task
    result = execute_callable(context=context, **execute_callable_kwargs)
  File "/home/airflow/.local/lib/python3.8/site-packages/airflow/providers/docker/operators/docker.py", line 502, in execute
    return self._run_image()
  File "/home/airflow/.local/lib/python3.8/site-packages/airflow/providers/docker/operators/docker.py", line 376, in _run_image
    return self._run_image_with_mounts(self.mounts, add_tmp_variable=False)
  File "/home/airflow/.local/lib/python3.8/site-packages/airflow/providers/docker/operators/docker.py", line 391, in _run_image_with_mounts
    self.container = self.cli.create_container(
  File "/home/airflow/.local/lib/python3.8/site-packages/docker/api/container.py", line 439, in create_container
    return self.create_container_from_config(config, name, platform)
  File "/home/airflow/.local/lib/python3.8/site-packages/docker/api/container.py", line 456, in create_container_from_config
    return self._result(res, True)
  File "/home/airflow/.local/lib/python3.8/site-packages/docker/api/client.py", line 271, in _result
    self._raise_for_status(response)
  File "/home/airflow/.local/lib/python3.8/site-packages/docker/api/client.py", line 267, in _raise_for_status
    raise create_api_error_from_http_exception(e) from e
  File "/home/airflow/.local/lib/python3.8/site-packages/docker/errors.py", line 39, in create_api_error_from_http_exception
    raise cls(e, response=response, explanation=explanation) from e
docker.errors.APIError: 400 Client Error for http+docker://localhost/v1.51/containers/create: Bad Request ("invalid mount config for type "bind": bind source path does not exist: /shared_data/Models")
[2025-09-13T16:31:21.560+0000] {taskinstance.py:1138} INFO - Marking task as FAILED. dag_id=ml_pipeline_orchestration, task_id=train_model, execution_date=20250913T162600, start_date=20250913T163120, end_date=20250913T163121
[2025-09-13T16:31:21.608+0000] {standard_task_runner.py:107} ERROR - Failed to execute job 99 for task train_model (400 Client Error for http+docker://localhost/v1.51/containers/create: Bad Request ("invalid mount config for type "bind": bind source path does not exist: /shared_data/Models"); 613)
[2025-09-13T16:31:21.637+0000] {local_task_job_runner.py:234} INFO - Task exited with return code 1
[2025-09-13T16:31:21.770+0000] {taskinstance.py:3280} INFO - 0 downstream tasks scheduled from follow-on schedule check
