[2025-09-16T21:23:30.944+0000] {taskinstance.py:1956} INFO - Dependencies all met for dep_context=non-requeueable deps ti=<TaskInstance: ml_pipeline_orchestration.log_experiments manual__2025-09-16T20:47:59.963201+00:00 [queued]>
[2025-09-16T21:23:30.972+0000] {taskinstance.py:1956} INFO - Dependencies all met for dep_context=requeueable deps ti=<TaskInstance: ml_pipeline_orchestration.log_experiments manual__2025-09-16T20:47:59.963201+00:00 [queued]>
[2025-09-16T21:23:30.974+0000] {taskinstance.py:2170} INFO - Starting attempt 1 of 2
[2025-09-16T21:23:31.066+0000] {taskinstance.py:2191} INFO - Executing <Task(DockerOperator): log_experiments> on 2025-09-16 20:47:59.963201+00:00
[2025-09-16T21:23:31.103+0000] {standard_task_runner.py:87} INFO - Running: ['***', 'tasks', 'run', 'ml_pipeline_orchestration', 'log_experiments', 'manual__2025-09-16T20:47:59.963201+00:00', '--job-id', '9', '--raw', '--subdir', 'DAGS_FOLDER/orchestration.py', '--cfg-path', '/tmp/tmpq64y5nt_']
[2025-09-16T21:23:31.114+0000] {standard_task_runner.py:88} INFO - Job 9: Subtask log_experiments
[2025-09-16T21:23:31.087+0000] {standard_task_runner.py:60} INFO - Started process 983 to run task
[2025-09-16T21:23:31.396+0000] {task_command.py:423} INFO - Running <TaskInstance: ml_pipeline_orchestration.log_experiments manual__2025-09-16T20:47:59.963201+00:00 [running]> on host 0e5b2843133d
[2025-09-16T21:23:31.840+0000] {taskinstance.py:2480} INFO - Exporting env vars: AIRFLOW_CTX_DAG_OWNER='Jerr-williams' AIRFLOW_CTX_DAG_ID='ml_pipeline_orchestration' AIRFLOW_CTX_TASK_ID='log_experiments' AIRFLOW_CTX_EXECUTION_DATE='2025-09-16T20:47:59.963201+00:00' AIRFLOW_CTX_TRY_NUMBER='1' AIRFLOW_CTX_DAG_RUN_ID='manual__2025-09-16T20:47:59.963201+00:00'
[2025-09-16T21:23:32.170+0000] {docker.py:359} INFO - Starting docker container from image 972111245465383674563253/prediction-apps:latest
[2025-09-16T21:23:54.876+0000] {docker.py:429} INFO - /usr/local/lib/python3.12/site-packages/mlflow/utils/requirements_utils.py:20: UserWarning: pkg_resources is deprecated as an API. See https://setuptools.pypa.io/en/latest/pkg_resources.html. The pkg_resources package is slated for removal as early as 2025-11-30. Refrain from using this package or pin to Setuptools<81.
  import pkg_resources  # noqa: TID251
[2025-09-16T21:25:05.767+0000] {docker.py:429} INFO - 2025/09/16 21:25:05 WARNING mlflow.utils.git_utils: Failed to import Git (the Git executable is probably not on your PATH), so Git SHA is not available. Error: Failed to initialize: Bad git executable.
The git executable must be specified in one of the following ways:
    - be included in your $PATH
    - be set via $GIT_PYTHON_GIT_EXECUTABLE
    - explicitly set via git.refresh(<full-path-to-git-executable>)

All git commands will error until this is rectified.

This initial message can be silenced or aggravated in the future by setting the
$GIT_PYTHON_REFRESH environment variable. Use one of the following values:
    - quiet|q|silence|s|silent|none|n|0: for no message or exception
    - warn|w|warning|log|l|1: for a warning message (logging level CRITICAL, displayed by default)
    - error|e|exception|raise|r|2: for a raised exception

Example:
    export GIT_PYTHON_REFRESH=quiet
[2025-09-16T21:28:12.231+0000] {docker.py:429} INFO - Logging the Experiements
Error setting up MLflow: API request to https://dagshub.com/jerremiahwilly/Customer-churn.mlflow/api/2.0/mlflow/experiments/get-by-name failed with exception HTTPSConnectionPool(host='dagshub.com', port=443): Max retries exceeded with url: /jerremiahwilly/Customer-churn.mlflow/api/2.0/mlflow/experiments/get-by-name?experiment_name=Customer+Churn+Prediction (Caused by NameResolutionError("<urllib3.connection.HTTPSConnection object at 0x7f19a382f4d0>: Failed to resolve 'dagshub.com' ([Errno -2] Name or service not known)"))
Error tracking logistic_regression: API request to https://dagshub.com/jerremiahwilly/Customer-churn.mlflow/api/2.0/mlflow/runs/create failed with exception HTTPSConnectionPool(host='dagshub.com', port=443): Max retries exceeded with url: /jerremiahwilly/Customer-churn.mlflow/api/2.0/mlflow/runs/create (Caused by NameResolutionError("<urllib3.connection.HTTPSConnection object at 0x7f19a350d010>: Failed to resolve 'dagshub.com' ([Errno -2] Name or service not known)"))
Error tracking random_forest: API request to https://dagshub.com/jerremiahwilly/Customer-churn.mlflow/api/2.0/mlflow/runs/create failed with exception HTTPSConnectionPool(host='dagshub.com', port=443): Max retries exceeded with url: /jerremiahwilly/Customer-churn.mlflow/api/2.0/mlflow/runs/create (Caused by NameResolutionError("<urllib3.connection.HTTPSConnection object at 0x7f19a34b3410>: Failed to resolve 'dagshub.com' ([Errno -2] Name or service not known)"))
Error tracking Gradient_Boosting: API request to https://dagshub.com/jerremiahwilly/Customer-churn.mlflow/api/2.0/mlflow/runs/create failed with exception HTTPSConnectionPool(host='dagshub.com', port=443): Max retries exceeded with url: /jerremiahwilly/Customer-churn.mlflow/api/2.0/mlflow/runs/create (Caused by NameResolutionError("<urllib3.connection.HTTPSConnection object at 0x7f19a350c9e0>: Failed to resolve 'dagshub.com' ([Errno -2] Name or service not known)"))
Successfully logged 0 experiments
[2025-09-16T21:28:15.974+0000] {taskinstance.py:1138} INFO - Marking task as SUCCESS. dag_id=ml_pipeline_orchestration, task_id=log_experiments, execution_date=20250916T204759, start_date=20250916T212330, end_date=20250916T212815
[2025-09-16T21:28:16.110+0000] {local_task_job_runner.py:234} INFO - Task exited with return code 0
[2025-09-16T21:28:16.249+0000] {taskinstance.py:3280} INFO - 1 downstream tasks scheduled from follow-on schedule check
