[2025-09-09T10:54:46.564+0000] {taskinstance.py:1956} INFO - Dependencies all met for dep_context=non-requeueable deps ti=<TaskInstance: ml_pipeline_orchestration.train_model manual__2025-09-09T10:54:31.661941+00:00 [queued]>
[2025-09-09T10:54:46.588+0000] {taskinstance.py:1956} INFO - Dependencies all met for dep_context=requeueable deps ti=<TaskInstance: ml_pipeline_orchestration.train_model manual__2025-09-09T10:54:31.661941+00:00 [queued]>
[2025-09-09T10:54:46.591+0000] {taskinstance.py:2170} INFO - Starting attempt 1 of 2
[2025-09-09T10:54:46.679+0000] {taskinstance.py:2191} INFO - Executing <Task(DockerOperator): train_model> on 2025-09-09 10:54:31.661941+00:00
[2025-09-09T10:54:46.700+0000] {standard_task_runner.py:60} INFO - Started process 548 to run task
[2025-09-09T10:54:46.709+0000] {standard_task_runner.py:87} INFO - Running: ['***', 'tasks', 'run', 'ml_pipeline_orchestration', 'train_model', 'manual__2025-09-09T10:54:31.661941+00:00', '--job-id', '27', '--raw', '--subdir', 'DAGS_FOLDER/orchestration.py', '--cfg-path', '/tmp/tmp8z_jv9i3']
[2025-09-09T10:54:46.717+0000] {standard_task_runner.py:88} INFO - Job 27: Subtask train_model
[2025-09-09T10:54:46.963+0000] {task_command.py:423} INFO - Running <TaskInstance: ml_pipeline_orchestration.train_model manual__2025-09-09T10:54:31.661941+00:00 [running]> on host 8ba9f5523319
[2025-09-09T10:54:47.472+0000] {taskinstance.py:2480} INFO - Exporting env vars: AIRFLOW_CTX_DAG_OWNER='Jerr-williams' AIRFLOW_CTX_DAG_ID='ml_pipeline_orchestration' AIRFLOW_CTX_TASK_ID='train_model' AIRFLOW_CTX_EXECUTION_DATE='2025-09-09T10:54:31.661941+00:00' AIRFLOW_CTX_TRY_NUMBER='1' AIRFLOW_CTX_DAG_RUN_ID='manual__2025-09-09T10:54:31.661941+00:00'
[2025-09-09T10:54:47.977+0000] {docker.py:486} INFO - Pulling docker image 972111245465383674563253/prediction-apps:latest
[2025-09-09T10:55:06.753+0000] {docker.py:500} INFO - latest: Pulling from 972111245465383674563253/prediction-apps
[2025-09-09T10:55:24.700+0000] {docker.py:500} INFO - 08e9596134ee: Pulling fs layer
[2025-09-09T10:55:24.703+0000] {docker.py:500} INFO - 20f4762c7702: Pulling fs layer
[2025-09-09T10:55:24.705+0000] {docker.py:500} INFO - 364475f8ab1d: Pulling fs layer
[2025-09-09T10:55:24.707+0000] {docker.py:500} INFO - a72dc0d7ef65: Pulling fs layer
[2025-09-09T10:55:28.003+0000] {docker.py:500} INFO - a72dc0d7ef65: Downloading
[2025-09-09T10:55:28.212+0000] {docker.py:500} INFO - a72dc0d7ef65: Download complete
[2025-09-09T10:55:29.033+0000] {docker.py:500} INFO - a72dc0d7ef65: Extracting
[2025-09-09T10:55:29.035+0000] {docker.py:500} INFO - 08e9596134ee: Downloading
[2025-09-09T10:55:29.621+0000] {docker.py:500} INFO - a72dc0d7ef65: Pull complete
[2025-09-09T10:55:30.914+0000] {docker.py:500} INFO - 364475f8ab1d: Downloading
[2025-09-09T10:55:31.113+0000] {docker.py:500} INFO - 364475f8ab1d: Download complete
[2025-09-09T10:55:39.468+0000] {docker.py:500} INFO - 20f4762c7702: Downloading
[2025-09-09T10:55:40.412+0000] {docker.py:500} INFO - 20f4762c7702: Download complete
[2025-09-09T10:55:40.417+0000] {docker.py:500} INFO - 20f4762c7702: Extracting
[2025-09-09T10:55:40.816+0000] {docker.py:500} INFO - 20f4762c7702: Pull complete
[2025-09-09T10:55:41.016+0000] {docker.py:500} INFO - 364475f8ab1d: Extracting
[2025-09-09T10:55:41.315+0000] {docker.py:500} INFO - 364475f8ab1d: Pull complete
[2025-09-09T11:41:25.629+0000] {docker.py:359} INFO - Starting docker container from image 972111245465383674563253/prediction-apps:latest
[2025-09-09T11:41:26.241+0000] {taskinstance.py:2698} ERROR - Task failed with exception
Traceback (most recent call last):
  File "/home/airflow/.local/lib/python3.8/site-packages/docker/api/client.py", line 265, in _raise_for_status
    response.raise_for_status()
  File "/home/airflow/.local/lib/python3.8/site-packages/requests/models.py", line 1021, in raise_for_status
    raise HTTPError(http_error_msg, response=self)
requests.exceptions.HTTPError: 404 Client Error: Not Found for url: http+docker://localhost/v1.51/containers/create

The above exception was the direct cause of the following exception:

Traceback (most recent call last):
  File "/home/airflow/.local/lib/python3.8/site-packages/airflow/models/taskinstance.py", line 433, in _execute_task
    result = execute_callable(context=context, **execute_callable_kwargs)
  File "/home/airflow/.local/lib/python3.8/site-packages/airflow/providers/docker/operators/docker.py", line 502, in execute
    return self._run_image()
  File "/home/airflow/.local/lib/python3.8/site-packages/airflow/providers/docker/operators/docker.py", line 376, in _run_image
    return self._run_image_with_mounts(self.mounts, add_tmp_variable=False)
  File "/home/airflow/.local/lib/python3.8/site-packages/airflow/providers/docker/operators/docker.py", line 391, in _run_image_with_mounts
    self.container = self.cli.create_container(
  File "/home/airflow/.local/lib/python3.8/site-packages/docker/api/container.py", line 439, in create_container
    return self.create_container_from_config(config, name, platform)
  File "/home/airflow/.local/lib/python3.8/site-packages/docker/api/container.py", line 456, in create_container_from_config
    return self._result(res, True)
  File "/home/airflow/.local/lib/python3.8/site-packages/docker/api/client.py", line 271, in _result
    self._raise_for_status(response)
  File "/home/airflow/.local/lib/python3.8/site-packages/docker/api/client.py", line 267, in _raise_for_status
    raise create_api_error_from_http_exception(e) from e
  File "/home/airflow/.local/lib/python3.8/site-packages/docker/errors.py", line 39, in create_api_error_from_http_exception
    raise cls(e, response=response, explanation=explanation) from e
docker.errors.ImageNotFound: 404 Client Error for http+docker://localhost/v1.51/containers/create: Not Found ("No such image: 972111245465383674563253/prediction-apps:latest")
[2025-09-09T11:41:26.433+0000] {taskinstance.py:1138} INFO - Marking task as UP_FOR_RETRY. dag_id=ml_pipeline_orchestration, task_id=train_model, execution_date=20250909T105431, start_date=20250909T105446, end_date=20250909T114126
[2025-09-09T11:41:26.548+0000] {standard_task_runner.py:107} ERROR - Failed to execute job 27 for task train_model (404 Client Error for http+docker://localhost/v1.51/containers/create: Not Found ("No such image: 972111245465383674563253/prediction-apps:latest"); 548)
[2025-09-09T11:41:26.587+0000] {local_task_job_runner.py:234} INFO - Task exited with return code 1
[2025-09-09T11:41:26.699+0000] {taskinstance.py:3280} INFO - 0 downstream tasks scheduled from follow-on schedule check
