[2025-09-01T04:47:24.984+0000] {taskinstance.py:1956} INFO - Dependencies all met for dep_context=non-requeueable deps ti=<TaskInstance: ml_pipeline_orchestration.train_model scheduled__2025-08-31T00:00:00+00:00 [queued]>
[2025-09-01T04:47:24.995+0000] {taskinstance.py:1956} INFO - Dependencies all met for dep_context=requeueable deps ti=<TaskInstance: ml_pipeline_orchestration.train_model scheduled__2025-08-31T00:00:00+00:00 [queued]>
[2025-09-01T04:47:24.996+0000] {taskinstance.py:2170} INFO - Starting attempt 2 of 2
[2025-09-01T04:47:25.117+0000] {taskinstance.py:2191} INFO - Executing <Task(DockerOperator): train_model> on 2025-08-31 00:00:00+00:00
[2025-09-01T04:47:25.148+0000] {standard_task_runner.py:60} INFO - Started process 408 to run task
[2025-09-01T04:47:25.154+0000] {standard_task_runner.py:87} INFO - Running: ['***', 'tasks', 'run', 'ml_pipeline_orchestration', 'train_model', 'scheduled__2025-08-31T00:00:00+00:00', '--job-id', '38', '--raw', '--subdir', 'DAGS_FOLDER/orchestration.py', '--cfg-path', '/tmp/tmp3wn_lt71']
[2025-09-01T04:47:25.158+0000] {standard_task_runner.py:88} INFO - Job 38: Subtask train_model
[2025-09-01T04:47:25.312+0000] {task_command.py:423} INFO - Running <TaskInstance: ml_pipeline_orchestration.train_model scheduled__2025-08-31T00:00:00+00:00 [running]> on host 9f4fe8d13603
[2025-09-01T04:47:25.580+0000] {taskinstance.py:2480} INFO - Exporting env vars: AIRFLOW_CTX_DAG_OWNER='Jerr-williams' AIRFLOW_CTX_DAG_ID='ml_pipeline_orchestration' AIRFLOW_CTX_TASK_ID='train_model' AIRFLOW_CTX_EXECUTION_DATE='2025-08-31T00:00:00+00:00' AIRFLOW_CTX_TRY_NUMBER='2' AIRFLOW_CTX_DAG_RUN_ID='scheduled__2025-08-31T00:00:00+00:00'
[2025-09-01T04:47:25.628+0000] {docker.py:359} INFO - Starting docker container from image 972111245465383674563253/prediction-churn-app:latest
[2025-09-01T04:47:25.644+0000] {docker.py:367} WARNING - Using remote engine or docker-in-docker and mounting temporary volume from host is not supported. Falling back to `mount_tmp_dir=False` mode. You can set `mount_tmp_dir` parameter to False to disable mounting and remove the warning
[2025-09-01T04:47:45.784+0000] {docker.py:429} INFO - === CUSTOMER CHURN PREDICTION TRAINING ===

1. Loading data...
[2025-09-01T04:47:45.785+0000] {docker.py:429} INFO - Traceback (most recent call last):
  File "/app/script/train.py", line 37, in <module>
    main()
  File "/app/script/train.py", line 20, in main
    df = load_data("data/raw/customer_churn.csv")
         ^^^^^^^^^^^^^^^^^^^^^^^^^^^^^^^^^^^^^^^^
  File "/app/src/data/load_data.py", line 11, in load_data
[2025-09-01T04:47:45.786+0000] {docker.py:429} INFO - raise FileNotFoundError(f"Data file not found: {file_path}")
FileNotFoundError: Data file not found: /app/data/raw/customer_churn.csv
[2025-09-01T04:47:50.566+0000] {taskinstance.py:2698} ERROR - Task failed with exception
Traceback (most recent call last):
  File "/home/airflow/.local/lib/python3.8/site-packages/docker/api/client.py", line 265, in _raise_for_status
    response.raise_for_status()
  File "/home/airflow/.local/lib/python3.8/site-packages/requests/models.py", line 1021, in raise_for_status
    raise HTTPError(http_error_msg, response=self)
requests.exceptions.HTTPError: 400 Client Error: Bad Request for url: http+docker://localhost/v1.48/containers/create?name=ml_train_20250831_20250831T000000

The above exception was the direct cause of the following exception:

Traceback (most recent call last):
  File "/home/airflow/.local/lib/python3.8/site-packages/airflow/providers/docker/operators/docker.py", line 364, in _run_image
    return self._run_image_with_mounts([*self.mounts, tmp_mount], add_tmp_variable=True)
  File "/home/airflow/.local/lib/python3.8/site-packages/airflow/providers/docker/operators/docker.py", line 391, in _run_image_with_mounts
    self.container = self.cli.create_container(
  File "/home/airflow/.local/lib/python3.8/site-packages/docker/api/container.py", line 439, in create_container
    return self.create_container_from_config(config, name, platform)
  File "/home/airflow/.local/lib/python3.8/site-packages/docker/api/container.py", line 456, in create_container_from_config
    return self._result(res, True)
  File "/home/airflow/.local/lib/python3.8/site-packages/docker/api/client.py", line 271, in _result
    self._raise_for_status(response)
  File "/home/airflow/.local/lib/python3.8/site-packages/docker/api/client.py", line 267, in _raise_for_status
    raise create_api_error_from_http_exception(e) from e
  File "/home/airflow/.local/lib/python3.8/site-packages/docker/errors.py", line 39, in create_api_error_from_http_exception
    raise cls(e, response=response, explanation=explanation) from e
docker.errors.APIError: 400 Client Error for http+docker://localhost/v1.48/containers/create?name=ml_train_20250831_20250831T000000: Bad Request ("invalid mount config for type "bind": bind source path does not exist: /tmp/airflowtmptymwoe0i")

During handling of the above exception, another exception occurred:

Traceback (most recent call last):
  File "/home/airflow/.local/lib/python3.8/site-packages/airflow/models/taskinstance.py", line 433, in _execute_task
    result = execute_callable(context=context, **execute_callable_kwargs)
  File "/home/airflow/.local/lib/python3.8/site-packages/airflow/providers/docker/operators/docker.py", line 502, in execute
    return self._run_image()
  File "/home/airflow/.local/lib/python3.8/site-packages/airflow/providers/docker/operators/docker.py", line 373, in _run_image
    return self._run_image_with_mounts(self.mounts, add_tmp_variable=False)
  File "/home/airflow/.local/lib/python3.8/site-packages/airflow/providers/docker/operators/docker.py", line 437, in _run_image_with_mounts
    raise DockerContainerFailedException(f"Docker container failed: {result!r}", logs=log_lines)
airflow.providers.docker.exceptions.DockerContainerFailedException: Docker container failed: {'StatusCode': 1}
[2025-09-01T04:47:50.681+0000] {taskinstance.py:1138} INFO - Marking task as FAILED. dag_id=ml_pipeline_orchestration, task_id=train_model, execution_date=20250831T000000, start_date=20250901T044724, end_date=20250901T044750
[2025-09-01T04:47:51.044+0000] {standard_task_runner.py:107} ERROR - Failed to execute job 38 for task train_model (Docker container failed: {'StatusCode': 1}; 408)
[2025-09-01T04:47:51.068+0000] {local_task_job_runner.py:234} INFO - Task exited with return code 1
[2025-09-01T04:47:51.148+0000] {taskinstance.py:3280} INFO - 0 downstream tasks scheduled from follow-on schedule check
