[2025-09-14T12:39:25.615+0000] {taskinstance.py:1956} INFO - Dependencies all met for dep_context=non-requeueable deps ti=<TaskInstance: ml_pipeline_orchestration.train_model manual__2025-09-14T12:32:41.033640+00:00 [queued]>
[2025-09-14T12:39:25.745+0000] {taskinstance.py:1956} INFO - Dependencies all met for dep_context=requeueable deps ti=<TaskInstance: ml_pipeline_orchestration.train_model manual__2025-09-14T12:32:41.033640+00:00 [queued]>
[2025-09-14T12:39:25.757+0000] {taskinstance.py:2170} INFO - Starting attempt 2 of 2
[2025-09-14T12:39:25.966+0000] {taskinstance.py:2191} INFO - Executing <Task(DockerOperator): train_model> on 2025-09-14 12:32:41.033640+00:00
[2025-09-14T12:39:26.053+0000] {standard_task_runner.py:87} INFO - Running: ['***', 'tasks', 'run', 'ml_pipeline_orchestration', 'train_model', 'manual__2025-09-14T12:32:41.033640+00:00', '--job-id', '7', '--raw', '--subdir', 'DAGS_FOLDER/orchestration.py', '--cfg-path', '/tmp/tmpuj2m68e9']
[2025-09-14T12:39:26.056+0000] {standard_task_runner.py:60} INFO - Started process 654 to run task
[2025-09-14T12:39:26.076+0000] {standard_task_runner.py:88} INFO - Job 7: Subtask train_model
[2025-09-14T12:39:26.817+0000] {task_command.py:423} INFO - Running <TaskInstance: ml_pipeline_orchestration.train_model manual__2025-09-14T12:32:41.033640+00:00 [running]> on host 6003dd60b185
[2025-09-14T12:39:27.684+0000] {taskinstance.py:2480} INFO - Exporting env vars: AIRFLOW_CTX_DAG_OWNER='Jerr-williams' AIRFLOW_CTX_DAG_ID='ml_pipeline_orchestration' AIRFLOW_CTX_TASK_ID='train_model' AIRFLOW_CTX_EXECUTION_DATE='2025-09-14T12:32:41.033640+00:00' AIRFLOW_CTX_TRY_NUMBER='2' AIRFLOW_CTX_DAG_RUN_ID='manual__2025-09-14T12:32:41.033640+00:00'
[2025-09-14T12:39:28.151+0000] {docker.py:359} INFO - Starting docker container from image 972111245465383674563253/prediction-apps:latest
[2025-09-14T12:40:55.777+0000] {docker.py:429} INFO - /app/src/data/clean_data.py:26: FutureWarning: The default of observed=False is deprecated and will be changed to True in a future version of pandas. Pass observed=False to retain current behavior or observed=True to adopt the future default and silence this warning.
  median_by_tenure = df_clean.groupby(pd.cut(df_clean['tenure'], bins=[0, 12, 24, 48, 72]))['total_charges'].median()
[2025-09-14T12:40:58.833+0000] {docker.py:429} INFO - === CUSTOMER CHURN PREDICTION TRAINING ===

1. Loading data...
Loaded 5000 rows and 14 columns

2. Cleaning data...
Starting data cleaning...
Removed 0 duplicate rows
Data cleaning completed
Removed 293 outliers from total_charges
Data cleaning completed. Final shape: (4707, 14)

3. Transforming data...
Starting data transformation...
Fitted encoder for gender
Fitted encoder for contract
Fitted encoder for internet_service
Fitted encoder for online_security
Fitted encoder for tech_support
Fitted encoder for streaming_tv
Fitted encoder for payment_method
Fitted encoder for paperless_billing
Train set: 3765 samples
Test set: 942 samples
All transformers saved to /app/Models/transformers.joblib
Data transformation completed

4. Training models...
Training logistic_regression...
[2025-09-14T12:41:21.232+0000] {job.py:213} ERROR - Job heartbeat got an exception
Traceback (most recent call last):
  File "/home/airflow/.local/lib/python3.8/site-packages/sqlalchemy/engine/base.py", line 3371, in _wrap_pool_connect
    return fn()
  File "/home/airflow/.local/lib/python3.8/site-packages/sqlalchemy/pool/base.py", line 327, in connect
    return _ConnectionFairy._checkout(self)
  File "/home/airflow/.local/lib/python3.8/site-packages/sqlalchemy/pool/base.py", line 894, in _checkout
    fairy = _ConnectionRecord.checkout(pool)
  File "/home/airflow/.local/lib/python3.8/site-packages/sqlalchemy/pool/base.py", line 493, in checkout
    rec = pool._do_get()
  File "/home/airflow/.local/lib/python3.8/site-packages/sqlalchemy/pool/impl.py", line 256, in _do_get
    return self._create_connection()
  File "/home/airflow/.local/lib/python3.8/site-packages/sqlalchemy/pool/base.py", line 273, in _create_connection
    return _ConnectionRecord(self)
  File "/home/airflow/.local/lib/python3.8/site-packages/sqlalchemy/pool/base.py", line 388, in __init__
    self.__connect()
  File "/home/airflow/.local/lib/python3.8/site-packages/sqlalchemy/pool/base.py", line 691, in __connect
    pool.logger.debug("Error on connect(): %s", e)
  File "/home/airflow/.local/lib/python3.8/site-packages/sqlalchemy/util/langhelpers.py", line 70, in __exit__
    compat.raise_(
  File "/home/airflow/.local/lib/python3.8/site-packages/sqlalchemy/util/compat.py", line 211, in raise_
    raise exception
  File "/home/airflow/.local/lib/python3.8/site-packages/sqlalchemy/pool/base.py", line 686, in __connect
    self.dbapi_connection = connection = pool._invoke_creator(self)
  File "/home/airflow/.local/lib/python3.8/site-packages/sqlalchemy/engine/create.py", line 574, in connect
    return dialect.connect(*cargs, **cparams)
  File "/home/airflow/.local/lib/python3.8/site-packages/sqlalchemy/engine/default.py", line 598, in connect
    return self.dbapi.connect(*cargs, **cparams)
  File "/home/airflow/.local/lib/python3.8/site-packages/psycopg2/__init__.py", line 122, in connect
    conn = _connect(dsn, connection_factory=connection_factory, **kwasync)
psycopg2.OperationalError: could not translate host name "postgres" to address: Temporary failure in name resolution


The above exception was the direct cause of the following exception:

Traceback (most recent call last):
  File "/home/airflow/.local/lib/python3.8/site-packages/airflow/jobs/job.py", line 187, in heartbeat
    self._merge_from(Job._fetch_from_db(self, session))
  File "/home/airflow/.local/lib/python3.8/site-packages/airflow/api_internal/internal_api_call.py", line 114, in wrapper
    return func(*args, **kwargs)
  File "/home/airflow/.local/lib/python3.8/site-packages/airflow/utils/session.py", line 76, in wrapper
    return func(*args, **kwargs)
  File "/home/airflow/.local/lib/python3.8/site-packages/airflow/jobs/job.py", line 308, in _fetch_from_db
    session.merge(job)
  File "/home/airflow/.local/lib/python3.8/site-packages/sqlalchemy/orm/session.py", line 3056, in merge
    return self._merge(
  File "/home/airflow/.local/lib/python3.8/site-packages/sqlalchemy/orm/session.py", line 3136, in _merge
    merged = self.get(
  File "/home/airflow/.local/lib/python3.8/site-packages/sqlalchemy/orm/session.py", line 2853, in get
    return self._get_impl(
  File "/home/airflow/.local/lib/python3.8/site-packages/sqlalchemy/orm/session.py", line 2975, in _get_impl
    return db_load_fn(
  File "/home/airflow/.local/lib/python3.8/site-packages/sqlalchemy/orm/loading.py", line 530, in load_on_pk_identity
    session.execute(
  File "/home/airflow/.local/lib/python3.8/site-packages/sqlalchemy/orm/session.py", line 1716, in execute
    conn = self._connection_for_bind(bind)
  File "/home/airflow/.local/lib/python3.8/site-packages/sqlalchemy/orm/session.py", line 1555, in _connection_for_bind
    return self._transaction._connection_for_bind(
  File "/home/airflow/.local/lib/python3.8/site-packages/sqlalchemy/orm/session.py", line 750, in _connection_for_bind
    conn = bind.connect()
  File "/home/airflow/.local/lib/python3.8/site-packages/sqlalchemy/future/engine.py", line 412, in connect
    return super(Engine, self).connect()
  File "/home/airflow/.local/lib/python3.8/site-packages/sqlalchemy/engine/base.py", line 3325, in connect
    return self._connection_cls(self, close_with_result=close_with_result)
  File "/home/airflow/.local/lib/python3.8/site-packages/sqlalchemy/engine/base.py", line 96, in __init__
    else engine.raw_connection()
  File "/home/airflow/.local/lib/python3.8/site-packages/sqlalchemy/engine/base.py", line 3404, in raw_connection
    return self._wrap_pool_connect(self.pool.connect, _connection)
  File "/home/airflow/.local/lib/python3.8/site-packages/sqlalchemy/engine/base.py", line 3374, in _wrap_pool_connect
    Connection._handle_dbapi_exception_noconnection(
  File "/home/airflow/.local/lib/python3.8/site-packages/sqlalchemy/engine/base.py", line 2208, in _handle_dbapi_exception_noconnection
    util.raise_(
  File "/home/airflow/.local/lib/python3.8/site-packages/sqlalchemy/util/compat.py", line 211, in raise_
    raise exception
  File "/home/airflow/.local/lib/python3.8/site-packages/sqlalchemy/engine/base.py", line 3371, in _wrap_pool_connect
    return fn()
  File "/home/airflow/.local/lib/python3.8/site-packages/sqlalchemy/pool/base.py", line 327, in connect
    return _ConnectionFairy._checkout(self)
  File "/home/airflow/.local/lib/python3.8/site-packages/sqlalchemy/pool/base.py", line 894, in _checkout
    fairy = _ConnectionRecord.checkout(pool)
  File "/home/airflow/.local/lib/python3.8/site-packages/sqlalchemy/pool/base.py", line 493, in checkout
    rec = pool._do_get()
  File "/home/airflow/.local/lib/python3.8/site-packages/sqlalchemy/pool/impl.py", line 256, in _do_get
    return self._create_connection()
  File "/home/airflow/.local/lib/python3.8/site-packages/sqlalchemy/pool/base.py", line 273, in _create_connection
    return _ConnectionRecord(self)
  File "/home/airflow/.local/lib/python3.8/site-packages/sqlalchemy/pool/base.py", line 388, in __init__
    self.__connect()
  File "/home/airflow/.local/lib/python3.8/site-packages/sqlalchemy/pool/base.py", line 691, in __connect
    pool.logger.debug("Error on connect(): %s", e)
  File "/home/airflow/.local/lib/python3.8/site-packages/sqlalchemy/util/langhelpers.py", line 70, in __exit__
    compat.raise_(
  File "/home/airflow/.local/lib/python3.8/site-packages/sqlalchemy/util/compat.py", line 211, in raise_
    raise exception
  File "/home/airflow/.local/lib/python3.8/site-packages/sqlalchemy/pool/base.py", line 686, in __connect
    self.dbapi_connection = connection = pool._invoke_creator(self)
  File "/home/airflow/.local/lib/python3.8/site-packages/sqlalchemy/engine/create.py", line 574, in connect
    return dialect.connect(*cargs, **cparams)
  File "/home/airflow/.local/lib/python3.8/site-packages/sqlalchemy/engine/default.py", line 598, in connect
    return self.dbapi.connect(*cargs, **cparams)
  File "/home/airflow/.local/lib/python3.8/site-packages/psycopg2/__init__.py", line 122, in connect
    conn = _connect(dsn, connection_factory=connection_factory, **kwasync)
sqlalchemy.exc.OperationalError: (psycopg2.OperationalError) could not translate host name "postgres" to address: Temporary failure in name resolution

(Background on this error at: https://sqlalche.me/e/14/e3q8)
[2025-09-14T12:42:12.027+0000] {job.py:221} ERROR - Job heartbeat failed with error. Scheduler is in unhealthy state
[2025-09-14T13:02:00.037+0000] {local_task_job_runner.py:211} ERROR - Heartbeat time limit exceeded!
[2025-09-14T13:02:12.332+0000] {process_utils.py:131} INFO - Sending 15 to group 654. PIDs of all processes in the group: [654]
[2025-09-14T13:02:13.806+0000] {process_utils.py:86} INFO - Sending the signal 15 to group 654
[2025-09-14T13:02:14.958+0000] {taskinstance.py:2450} ERROR - Received SIGTERM. Terminating subprocesses.
[2025-09-14T13:02:16.511+0000] {docker.py:521} INFO - Stopping docker container
[2025-09-14T13:03:08.022+0000] {logging_mixin.py:188} WARNING - --- Logging error ---
[2025-09-14T13:03:10.882+0000] {logging_mixin.py:188} WARNING - Traceback (most recent call last):
[2025-09-14T13:03:10.885+0000] {logging_mixin.py:188} WARNING -   File "/usr/local/lib/python3.8/logging/__init__.py", line 1085, in emit
    msg = self.format(record)
[2025-09-14T13:03:10.887+0000] {logging_mixin.py:188} WARNING -   File "/usr/local/lib/python3.8/logging/__init__.py", line 929, in format
    return fmt.format(record)
[2025-09-14T13:03:10.889+0000] {logging_mixin.py:188} WARNING -   File "/usr/local/lib/python3.8/logging/__init__.py", line 670, in format
    record.asctime = self.formatTime(record, self.datefmt)
[2025-09-14T13:03:10.890+0000] {logging_mixin.py:188} WARNING -   File "/home/***/.local/lib/python3.8/site-packages/***/utils/log/timezone_aware.py", line 42, in formatTime
    dt = pendulum.from_timestamp(record.created, tz=pendulum.local_timezone())
[2025-09-14T13:03:11.251+0000] {logging_mixin.py:188} WARNING -   File "/home/***/.local/lib/python3.8/site-packages/pendulum/__init__.py", line 297, in from_timestamp
    dt = datetime(
[2025-09-14T13:03:11.258+0000] {logging_mixin.py:188} WARNING -   File "/home/***/.local/lib/python3.8/site-packages/pendulum/__init__.py", line 143, in datetime
    return DateTime.create(
[2025-09-14T13:03:11.263+0000] {logging_mixin.py:188} WARNING -   File "/home/***/.local/lib/python3.8/site-packages/pendulum/datetime.py", line 110, in create
    dt = tz.convert(dt, raise_on_unknown_times=raise_on_unknown_times)
[2025-09-14T13:03:11.268+0000] {logging_mixin.py:188} WARNING -   File "/home/***/.local/lib/python3.8/site-packages/pendulum/tz/timezone.py", line 107, in convert
    offset_before = cast(
[2025-09-14T13:03:11.275+0000] {logging_mixin.py:188} WARNING -   File "/usr/local/lib/python3.8/typing.py", line 1149, in cast
    def cast(typ, val):
[2025-09-14T13:03:11.280+0000] {logging_mixin.py:188} WARNING -   File "/home/***/.local/lib/python3.8/site-packages/***/models/taskinstance.py", line 2452, in signal_handler
    raise AirflowException("Task received SIGTERM signal")
[2025-09-14T13:03:11.287+0000] {logging_mixin.py:188} WARNING - ***.exceptions.AirflowException: Task received SIGTERM signal
[2025-09-14T13:03:11.292+0000] {logging_mixin.py:188} WARNING - Call stack:
[2025-09-14T13:03:14.019+0000] {process_utils.py:149} WARNING - process psutil.Process(pid=654, name='airflow task ru', status='disk-sleep', started='12:39:25') did not respond to SIGTERM. Trying SIGKILL
[2025-09-14T13:03:16.151+0000] {process_utils.py:86} INFO - Sending the signal 9 to group 654
[2025-09-14T13:03:16.420+0000] {process_utils.py:79} INFO - Process psutil.Process(pid=654, name='airflow task ru', status='terminated', exitcode=<Negsignal.SIGKILL: -9>, started='12:39:25') (654) terminated with exit code -9
[2025-09-14T13:03:16.482+0000] {standard_task_runner.py:175} ERROR - Job 7 was killed before it finished (likely due to running out of memory)
