[2025-09-01T04:40:10.428+0000] {taskinstance.py:1956} INFO - Dependencies all met for dep_context=non-requeueable deps ti=<TaskInstance: ml_pipeline_orchestration2.train_model scheduled__2025-08-31T00:00:00+00:00 [queued]>
[2025-09-01T04:40:10.440+0000] {taskinstance.py:1956} INFO - Dependencies all met for dep_context=requeueable deps ti=<TaskInstance: ml_pipeline_orchestration2.train_model scheduled__2025-08-31T00:00:00+00:00 [queued]>
[2025-09-01T04:40:10.441+0000] {taskinstance.py:2170} INFO - Starting attempt 1 of 2
[2025-09-01T04:40:11.235+0000] {taskinstance.py:2191} INFO - Executing <Task(DockerOperator): train_model> on 2025-08-31 00:00:00+00:00
[2025-09-01T04:40:11.243+0000] {standard_task_runner.py:60} INFO - Started process 199 to run task
[2025-09-01T04:40:11.249+0000] {standard_task_runner.py:87} INFO - Running: ['***', 'tasks', 'run', 'ml_pipeline_orchestration2', 'train_model', 'scheduled__2025-08-31T00:00:00+00:00', '--job-id', '36', '--raw', '--subdir', 'DAGS_FOLDER/try.py', '--cfg-path', '/tmp/tmp8s4m0ap7']
[2025-09-01T04:40:11.253+0000] {standard_task_runner.py:88} INFO - Job 36: Subtask train_model
[2025-09-01T04:40:11.994+0000] {task_command.py:423} INFO - Running <TaskInstance: ml_pipeline_orchestration2.train_model scheduled__2025-08-31T00:00:00+00:00 [running]> on host 9f4fe8d13603
[2025-09-01T04:40:13.143+0000] {taskinstance.py:2480} INFO - Exporting env vars: AIRFLOW_CTX_DAG_OWNER='Jeremiah-williams' AIRFLOW_CTX_DAG_ID='ml_pipeline_orchestration2' AIRFLOW_CTX_TASK_ID='train_model' AIRFLOW_CTX_EXECUTION_DATE='2025-08-31T00:00:00+00:00' AIRFLOW_CTX_TRY_NUMBER='1' AIRFLOW_CTX_DAG_RUN_ID='scheduled__2025-08-31T00:00:00+00:00'
[2025-09-01T04:40:13.193+0000] {docker.py:359} INFO - Starting docker container from image 972111245465383674563253/prediction-churn-app:latest
[2025-09-01T04:40:13.205+0000] {taskinstance.py:2698} ERROR - Task failed with exception
Traceback (most recent call last):
  File "/home/airflow/.local/lib/python3.8/site-packages/docker/api/client.py", line 265, in _raise_for_status
    response.raise_for_status()
  File "/home/airflow/.local/lib/python3.8/site-packages/requests/models.py", line 1021, in raise_for_status
    raise HTTPError(http_error_msg, response=self)
requests.exceptions.HTTPError: 400 Client Error: Bad Request for url: http+docker://localhost/v1.48/containers/create

The above exception was the direct cause of the following exception:

Traceback (most recent call last):
  File "/home/airflow/.local/lib/python3.8/site-packages/airflow/models/taskinstance.py", line 433, in _execute_task
    result = execute_callable(context=context, **execute_callable_kwargs)
  File "/home/airflow/.local/lib/python3.8/site-packages/airflow/providers/docker/operators/docker.py", line 502, in execute
    return self._run_image()
  File "/home/airflow/.local/lib/python3.8/site-packages/airflow/providers/docker/operators/docker.py", line 364, in _run_image
    return self._run_image_with_mounts([*self.mounts, tmp_mount], add_tmp_variable=True)
  File "/home/airflow/.local/lib/python3.8/site-packages/airflow/providers/docker/operators/docker.py", line 391, in _run_image_with_mounts
    self.container = self.cli.create_container(
  File "/home/airflow/.local/lib/python3.8/site-packages/docker/api/container.py", line 439, in create_container
    return self.create_container_from_config(config, name, platform)
  File "/home/airflow/.local/lib/python3.8/site-packages/docker/api/container.py", line 456, in create_container_from_config
    return self._result(res, True)
  File "/home/airflow/.local/lib/python3.8/site-packages/docker/api/client.py", line 271, in _result
    self._raise_for_status(response)
  File "/home/airflow/.local/lib/python3.8/site-packages/docker/api/client.py", line 267, in _raise_for_status
    raise create_api_error_from_http_exception(e) from e
  File "/home/airflow/.local/lib/python3.8/site-packages/docker/errors.py", line 39, in create_api_error_from_http_exception
    raise cls(e, response=response, explanation=explanation) from e
docker.errors.APIError: 400 Client Error for http+docker://localhost/v1.48/containers/create: Bad Request ("invalid JSON: json: cannot unmarshal string into Go struct field HostConfig.HostConfig.Mounts of type mount.Mount")
[2025-09-01T04:40:13.226+0000] {taskinstance.py:1138} INFO - Marking task as UP_FOR_RETRY. dag_id=ml_pipeline_orchestration2, task_id=train_model, execution_date=20250831T000000, start_date=20250901T044010, end_date=20250901T044013
[2025-09-01T04:40:14.443+0000] {standard_task_runner.py:107} ERROR - Failed to execute job 36 for task train_model (400 Client Error for http+docker://localhost/v1.48/containers/create: Bad Request ("invalid JSON: json: cannot unmarshal string into Go struct field HostConfig.HostConfig.Mounts of type mount.Mount"); 199)
[2025-09-01T04:40:14.475+0000] {local_task_job_runner.py:234} INFO - Task exited with return code 1
[2025-09-01T04:40:14.514+0000] {taskinstance.py:3280} INFO - 0 downstream tasks scheduled from follow-on schedule check
