[2025-08-31T12:12:46.710+0000] {taskinstance.py:1956} INFO - Dependencies all met for dep_context=non-requeueable deps ti=<TaskInstance: ml_pipeline_orchestration.train_model manual__2025-08-31T12:02:12.078511+00:00 [queued]>
[2025-08-31T12:12:46.956+0000] {taskinstance.py:1956} INFO - Dependencies all met for dep_context=requeueable deps ti=<TaskInstance: ml_pipeline_orchestration.train_model manual__2025-08-31T12:02:12.078511+00:00 [queued]>
[2025-08-31T12:12:47.204+0000] {taskinstance.py:2170} INFO - Starting attempt 2 of 2
[2025-08-31T12:12:47.593+0000] {taskinstance.py:2191} INFO - Executing <Task(DockerOperator): train_model> on 2025-08-31 12:02:12.078511+00:00
[2025-08-31T12:12:47.600+0000] {standard_task_runner.py:60} INFO - Started process 1242 to run task
[2025-08-31T12:12:47.606+0000] {standard_task_runner.py:87} INFO - Running: ['***', 'tasks', 'run', 'ml_pipeline_orchestration', 'train_model', 'manual__2025-08-31T12:02:12.078511+00:00', '--job-id', '31', '--raw', '--subdir', 'DAGS_FOLDER/orchestration.py', '--cfg-path', '/tmp/tmptf64f12p']
[2025-08-31T12:12:47.610+0000] {standard_task_runner.py:88} INFO - Job 31: Subtask train_model
[2025-08-31T12:12:48.969+0000] {task_command.py:423} INFO - Running <TaskInstance: ml_pipeline_orchestration.train_model manual__2025-08-31T12:02:12.078511+00:00 [running]> on host e7df5efbc762
[2025-08-31T12:12:49.370+0000] {taskinstance.py:2480} INFO - Exporting env vars: AIRFLOW_CTX_DAG_OWNER='Jerr-williams' AIRFLOW_CTX_DAG_ID='ml_pipeline_orchestration' AIRFLOW_CTX_TASK_ID='train_model' AIRFLOW_CTX_EXECUTION_DATE='2025-08-31T12:02:12.078511+00:00' AIRFLOW_CTX_TRY_NUMBER='2' AIRFLOW_CTX_DAG_RUN_ID='manual__2025-08-31T12:02:12.078511+00:00'
[2025-08-31T12:12:49.741+0000] {docker.py:359} INFO - Starting docker container from image 972111245465383674563253/prediction-churn-app:latest
[2025-08-31T12:13:16.944+0000] {docker.py:429} INFO - === CUSTOMER CHURN PREDICTION TRAINING ===

1. Loading data...
[2025-08-31T12:13:16.945+0000] {docker.py:429} INFO - Traceback (most recent call last):
  File "/app/script/train.py", line 37, in <module>
    main()
  File "/app/script/train.py", line 20, in main
[2025-08-31T12:13:16.946+0000] {docker.py:429} INFO - df = load_data("data/raw/customer_churn.csv")
[2025-08-31T12:13:16.946+0000] {docker.py:429} INFO - ^^^^^^^^^^^^^^^^^^^^^^^^^^^^^^^^^^^^^^^^
  File "/app/src/data/load_data.py", line 11, in load_data
[2025-08-31T12:13:16.947+0000] {docker.py:429} INFO - raise FileNotFoundError(f"Data file not found: {file_path}")
[2025-08-31T12:13:16.948+0000] {docker.py:429} INFO - FileNotFoundError: Data file not found: /app/data/raw/customer_churn.csv
[2025-08-31T12:13:26.560+0000] {taskinstance.py:2698} ERROR - Task failed with exception
Traceback (most recent call last):
  File "/home/airflow/.local/lib/python3.8/site-packages/airflow/models/taskinstance.py", line 433, in _execute_task
    result = execute_callable(context=context, **execute_callable_kwargs)
  File "/home/airflow/.local/lib/python3.8/site-packages/airflow/providers/docker/operators/docker.py", line 502, in execute
    return self._run_image()
  File "/home/airflow/.local/lib/python3.8/site-packages/airflow/providers/docker/operators/docker.py", line 376, in _run_image
    return self._run_image_with_mounts(self.mounts, add_tmp_variable=False)
  File "/home/airflow/.local/lib/python3.8/site-packages/airflow/providers/docker/operators/docker.py", line 437, in _run_image_with_mounts
    raise DockerContainerFailedException(f"Docker container failed: {result!r}", logs=log_lines)
airflow.providers.docker.exceptions.DockerContainerFailedException: Docker container failed: {'StatusCode': 1}
[2025-08-31T12:13:26.566+0000] {taskinstance.py:1138} INFO - Marking task as FAILED. dag_id=ml_pipeline_orchestration, task_id=train_model, execution_date=20250831T120212, start_date=20250831T121246, end_date=20250831T121326
[2025-08-31T12:13:27.184+0000] {standard_task_runner.py:107} ERROR - Failed to execute job 31 for task train_model (Docker container failed: {'StatusCode': 1}; 1242)
[2025-08-31T12:13:27.294+0000] {local_task_job_runner.py:234} INFO - Task exited with return code 1
[2025-08-31T12:13:27.549+0000] {taskinstance.py:3280} INFO - 0 downstream tasks scheduled from follow-on schedule check
