[2025-09-15T11:46:13.907+0000] {taskinstance.py:1956} INFO - Dependencies all met for dep_context=non-requeueable deps ti=<TaskInstance: just_orchestration.train_model scheduled__2025-09-14T00:00:00+00:00 [queued]>
[2025-09-15T11:46:14.050+0000] {taskinstance.py:1956} INFO - Dependencies all met for dep_context=requeueable deps ti=<TaskInstance: just_orchestration.train_model scheduled__2025-09-14T00:00:00+00:00 [queued]>
[2025-09-15T11:46:14.060+0000] {taskinstance.py:2170} INFO - Starting attempt 1 of 2
[2025-09-15T11:46:14.303+0000] {taskinstance.py:2191} INFO - Executing <Task(DockerOperator): train_model> on 2025-09-14 00:00:00+00:00
[2025-09-15T11:46:14.368+0000] {standard_task_runner.py:60} INFO - Started process 350 to run task
[2025-09-15T11:46:14.407+0000] {standard_task_runner.py:87} INFO - Running: ['***', 'tasks', 'run', 'just_orchestration', 'train_model', 'scheduled__2025-09-14T00:00:00+00:00', '--job-id', '24', '--raw', '--subdir', 'DAGS_FOLDER/another.py', '--cfg-path', '/tmp/tmpfqa2b43a']
[2025-09-15T11:46:14.430+0000] {standard_task_runner.py:88} INFO - Job 24: Subtask train_model
[2025-09-15T11:46:15.174+0000] {task_command.py:423} INFO - Running <TaskInstance: just_orchestration.train_model scheduled__2025-09-14T00:00:00+00:00 [running]> on host bc129d667b4c
[2025-09-15T11:46:16.589+0000] {taskinstance.py:2480} INFO - Exporting env vars: AIRFLOW_CTX_DAG_OWNER='williams' AIRFLOW_CTX_DAG_ID='just_orchestration' AIRFLOW_CTX_TASK_ID='train_model' AIRFLOW_CTX_EXECUTION_DATE='2025-09-14T00:00:00+00:00' AIRFLOW_CTX_TRY_NUMBER='1' AIRFLOW_CTX_DAG_RUN_ID='scheduled__2025-09-14T00:00:00+00:00'
[2025-09-15T11:46:19.873+0000] {docker.py:359} INFO - Starting docker container from image 972111245465383674563253/prediction-apps:latest
[2025-09-15T11:46:21.313+0000] {taskinstance.py:2698} ERROR - Task failed with exception
Traceback (most recent call last):
  File "/home/airflow/.local/lib/python3.8/site-packages/docker/api/client.py", line 265, in _raise_for_status
    response.raise_for_status()
  File "/home/airflow/.local/lib/python3.8/site-packages/requests/models.py", line 1021, in raise_for_status
    raise HTTPError(http_error_msg, response=self)
requests.exceptions.HTTPError: 400 Client Error: Bad Request for url: http+docker://localhost/v1.51/containers/create

The above exception was the direct cause of the following exception:

Traceback (most recent call last):
  File "/home/airflow/.local/lib/python3.8/site-packages/airflow/models/taskinstance.py", line 433, in _execute_task
    result = execute_callable(context=context, **execute_callable_kwargs)
  File "/home/airflow/.local/lib/python3.8/site-packages/airflow/providers/docker/operators/docker.py", line 502, in execute
    return self._run_image()
  File "/home/airflow/.local/lib/python3.8/site-packages/airflow/providers/docker/operators/docker.py", line 364, in _run_image
    return self._run_image_with_mounts([*self.mounts, tmp_mount], add_tmp_variable=True)
  File "/home/airflow/.local/lib/python3.8/site-packages/airflow/providers/docker/operators/docker.py", line 391, in _run_image_with_mounts
    self.container = self.cli.create_container(
  File "/home/airflow/.local/lib/python3.8/site-packages/docker/api/container.py", line 439, in create_container
    return self.create_container_from_config(config, name, platform)
  File "/home/airflow/.local/lib/python3.8/site-packages/docker/api/container.py", line 456, in create_container_from_config
    return self._result(res, True)
  File "/home/airflow/.local/lib/python3.8/site-packages/docker/api/client.py", line 271, in _result
    self._raise_for_status(response)
  File "/home/airflow/.local/lib/python3.8/site-packages/docker/api/client.py", line 267, in _raise_for_status
    raise create_api_error_from_http_exception(e) from e
  File "/home/airflow/.local/lib/python3.8/site-packages/docker/errors.py", line 39, in create_api_error_from_http_exception
    raise cls(e, response=response, explanation=explanation) from e
docker.errors.APIError: 400 Client Error for http+docker://localhost/v1.51/containers/create: Bad Request ("invalid mount config for type "bind": bind source path does not exist: /opt/Models")
[2025-09-15T11:46:22.242+0000] {taskinstance.py:1138} INFO - Marking task as UP_FOR_RETRY. dag_id=just_orchestration, task_id=train_model, execution_date=20250914T000000, start_date=20250915T114613, end_date=20250915T114622
[2025-09-15T11:46:22.675+0000] {standard_task_runner.py:107} ERROR - Failed to execute job 24 for task train_model (400 Client Error for http+docker://localhost/v1.51/containers/create: Bad Request ("invalid mount config for type "bind": bind source path does not exist: /opt/Models"); 350)
[2025-09-15T11:46:22.895+0000] {local_task_job_runner.py:234} INFO - Task exited with return code 1
[2025-09-15T11:46:24.999+0000] {taskinstance.py:3280} INFO - 0 downstream tasks scheduled from follow-on schedule check
